[2020-12-06 22:50:25,471] {taskinstance.py:669} INFO - Dependencies all met for <TaskInstance: us_covid_daily_report_pipeline.upload_file_to_s3 2020-12-04T00:00:00+00:00 [queued]>
[2020-12-06 22:50:25,530] {taskinstance.py:669} INFO - Dependencies all met for <TaskInstance: us_covid_daily_report_pipeline.upload_file_to_s3 2020-12-04T00:00:00+00:00 [queued]>
[2020-12-06 22:50:25,531] {taskinstance.py:879} INFO - 
--------------------------------------------------------------------------------
[2020-12-06 22:50:25,532] {taskinstance.py:880} INFO - Starting attempt 1 of 1
[2020-12-06 22:50:25,532] {taskinstance.py:881} INFO - 
--------------------------------------------------------------------------------
[2020-12-06 22:50:25,544] {taskinstance.py:900} INFO - Executing <Task(PythonOperator): upload_file_to_s3> on 2020-12-04T00:00:00+00:00
[2020-12-06 22:50:25,549] {standard_task_runner.py:53} INFO - Started process 5904 to run task
[2020-12-06 22:50:25,672] {logging_mixin.py:112} INFO - Running %s on host %s <TaskInstance: us_covid_daily_report_pipeline.upload_file_to_s3 2020-12-04T00:00:00+00:00 [running]> 0d17e5047b06
[2020-12-06 22:50:26,052] {logging_mixin.py:112} INFO - [2020-12-06 22:50:26,052] {S3_hook.py:209} INFO - Not Found
[2020-12-06 22:50:26,115] {taskinstance.py:1145} ERROR - [Errno 2] No such file or directory: '../data/20201204.json'
Traceback (most recent call last):
  File "/home/airflow/.local/lib/python3.6/site-packages/airflow/models/taskinstance.py", line 983, in _run_raw_task
    result = task_copy.execute(context=context)
  File "/home/airflow/.local/lib/python3.6/site-packages/airflow/operators/python_operator.py", line 113, in execute
    return_value = self.execute_callable()
  File "/home/airflow/.local/lib/python3.6/site-packages/airflow/operators/python_operator.py", line 118, in execute_callable
    return self.python_callable(*self.op_args, **self.op_kwargs)
  File "/opt/airflow/dags/us_covid_daily_report_pipeline.py", line 12, in upload_file_to_S3_with_hook
    hook.load_file(filename, key, bucket_name)
  File "/home/airflow/.local/lib/python3.6/site-packages/airflow/hooks/S3_hook.py", line 373, in load_file
    client.upload_file(filename, bucket_name, key, ExtraArgs=extra_args)
  File "/home/airflow/.local/lib/python3.6/site-packages/boto3/s3/inject.py", line 131, in upload_file
    extra_args=ExtraArgs, callback=Callback)
  File "/home/airflow/.local/lib/python3.6/site-packages/boto3/s3/transfer.py", line 279, in upload_file
    future.result()
  File "/home/airflow/.local/lib/python3.6/site-packages/s3transfer/futures.py", line 106, in result
    return self._coordinator.result()
  File "/home/airflow/.local/lib/python3.6/site-packages/s3transfer/futures.py", line 265, in result
    raise self._exception
  File "/home/airflow/.local/lib/python3.6/site-packages/s3transfer/tasks.py", line 255, in _main
    self._submit(transfer_future=transfer_future, **kwargs)
  File "/home/airflow/.local/lib/python3.6/site-packages/s3transfer/upload.py", line 549, in _submit
    upload_input_manager.provide_transfer_size(transfer_future)
  File "/home/airflow/.local/lib/python3.6/site-packages/s3transfer/upload.py", line 237, in provide_transfer_size
    transfer_future.meta.call_args.fileobj))
  File "/home/airflow/.local/lib/python3.6/site-packages/s3transfer/utils.py", line 245, in get_file_size
    return os.path.getsize(filename)
  File "/usr/local/lib/python3.6/genericpath.py", line 50, in getsize
    return os.stat(filename).st_size
FileNotFoundError: [Errno 2] No such file or directory: '../data/20201204.json'
[2020-12-06 22:50:26,123] {taskinstance.py:1202} INFO - Marking task as FAILED.dag_id=us_covid_daily_report_pipeline, task_id=upload_file_to_s3, execution_date=20201204T000000, start_date=20201206T225025, end_date=20201206T225026
[2020-12-06 22:50:35,401] {logging_mixin.py:112} INFO - [2020-12-06 22:50:35,400] {local_task_job.py:103} INFO - Task exited with return code 1
