[2020-12-07 00:12:37,815] {taskinstance.py:669} INFO - Dependencies all met for <TaskInstance: us_covid_daily_report_pipeline.upload_file_to_s3 2020-12-06T00:00:00+00:00 [queued]>
[2020-12-07 00:12:38,122] {taskinstance.py:669} INFO - Dependencies all met for <TaskInstance: us_covid_daily_report_pipeline.upload_file_to_s3 2020-12-06T00:00:00+00:00 [queued]>
[2020-12-07 00:12:38,127] {taskinstance.py:879} INFO - 
--------------------------------------------------------------------------------
[2020-12-07 00:12:38,133] {taskinstance.py:880} INFO - Starting attempt 1 of 1
[2020-12-07 00:12:38,143] {taskinstance.py:881} INFO - 
--------------------------------------------------------------------------------
[2020-12-07 00:12:38,351] {taskinstance.py:900} INFO - Executing <Task(PythonOperator): upload_file_to_s3> on 2020-12-06T00:00:00+00:00
[2020-12-07 00:12:38,388] {standard_task_runner.py:53} INFO - Started process 11393 to run task
[2020-12-07 00:12:39,324] {logging_mixin.py:112} INFO - Running %s on host %s <TaskInstance: us_covid_daily_report_pipeline.upload_file_to_s3 2020-12-06T00:00:00+00:00 [running]> 0d17e5047b06
[2020-12-07 00:12:44,136] {logging_mixin.py:112} INFO - [2020-12-07 00:12:44,133] {S3_hook.py:209} INFO - Forbidden
[2020-12-07 00:12:45,088] {taskinstance.py:1145} ERROR - Failed to upload ./data/20201206.json to datasets-jduran9987/20201206.json: An error occurred (RequestTimeTooSkewed) when calling the PutObject operation: The difference between the request time and the current time is too large.
Traceback (most recent call last):
  File "/home/airflow/.local/lib/python3.6/site-packages/boto3/s3/transfer.py", line 279, in upload_file
    future.result()
  File "/home/airflow/.local/lib/python3.6/site-packages/s3transfer/futures.py", line 106, in result
    return self._coordinator.result()
  File "/home/airflow/.local/lib/python3.6/site-packages/s3transfer/futures.py", line 265, in result
    raise self._exception
  File "/home/airflow/.local/lib/python3.6/site-packages/s3transfer/tasks.py", line 126, in __call__
    return self._execute_main(kwargs)
  File "/home/airflow/.local/lib/python3.6/site-packages/s3transfer/tasks.py", line 150, in _execute_main
    return_value = self._main(**kwargs)
  File "/home/airflow/.local/lib/python3.6/site-packages/s3transfer/upload.py", line 692, in _main
    client.put_object(Bucket=bucket, Key=key, Body=body, **extra_args)
  File "/home/airflow/.local/lib/python3.6/site-packages/botocore/client.py", line 316, in _api_call
    return self._make_api_call(operation_name, kwargs)
  File "/home/airflow/.local/lib/python3.6/site-packages/botocore/client.py", line 626, in _make_api_call
    raise error_class(parsed_response, operation_name)
botocore.exceptions.ClientError: An error occurred (RequestTimeTooSkewed) when calling the PutObject operation: The difference between the request time and the current time is too large.

During handling of the above exception, another exception occurred:

Traceback (most recent call last):
  File "/home/airflow/.local/lib/python3.6/site-packages/airflow/models/taskinstance.py", line 983, in _run_raw_task
    result = task_copy.execute(context=context)
  File "/home/airflow/.local/lib/python3.6/site-packages/airflow/operators/python_operator.py", line 113, in execute
    return_value = self.execute_callable()
  File "/home/airflow/.local/lib/python3.6/site-packages/airflow/operators/python_operator.py", line 118, in execute_callable
    return self.python_callable(*self.op_args, **self.op_kwargs)
  File "/opt/airflow/dags/us_covid_daily_report_pipeline.py", line 12, in upload_file_to_S3_with_hook
    hook.load_file(filename, key, bucket_name)
  File "/home/airflow/.local/lib/python3.6/site-packages/airflow/hooks/S3_hook.py", line 373, in load_file
    client.upload_file(filename, bucket_name, key, ExtraArgs=extra_args)
  File "/home/airflow/.local/lib/python3.6/site-packages/boto3/s3/inject.py", line 131, in upload_file
    extra_args=ExtraArgs, callback=Callback)
  File "/home/airflow/.local/lib/python3.6/site-packages/boto3/s3/transfer.py", line 287, in upload_file
    filename, '/'.join([bucket, key]), e))
boto3.exceptions.S3UploadFailedError: Failed to upload ./data/20201206.json to datasets-jduran9987/20201206.json: An error occurred (RequestTimeTooSkewed) when calling the PutObject operation: The difference between the request time and the current time is too large.
[2020-12-07 00:12:45,138] {taskinstance.py:1202} INFO - Marking task as FAILED.dag_id=us_covid_daily_report_pipeline, task_id=upload_file_to_s3, execution_date=20201206T000000, start_date=20201207T001237, end_date=20201207T001245
[2020-12-07 00:12:47,442] {logging_mixin.py:112} INFO - [2020-12-07 00:12:47,440] {local_task_job.py:103} INFO - Task exited with return code 1
