[2020-12-06 22:09:31,457] {taskinstance.py:669} INFO - Dependencies all met for <TaskInstance: us_covid_daily_report_pipeline.upload_file_to_s3 2020-12-02T00:00:00+00:00 [queued]>
[2020-12-06 22:09:31,501] {taskinstance.py:669} INFO - Dependencies all met for <TaskInstance: us_covid_daily_report_pipeline.upload_file_to_s3 2020-12-02T00:00:00+00:00 [queued]>
[2020-12-06 22:09:31,501] {taskinstance.py:879} INFO - 
--------------------------------------------------------------------------------
[2020-12-06 22:09:31,502] {taskinstance.py:880} INFO - Starting attempt 2 of 2
[2020-12-06 22:09:31,502] {taskinstance.py:881} INFO - 
--------------------------------------------------------------------------------
[2020-12-06 22:09:31,510] {taskinstance.py:900} INFO - Executing <Task(PythonOperator): upload_file_to_s3> on 2020-12-02T00:00:00+00:00
[2020-12-06 22:09:31,515] {standard_task_runner.py:53} INFO - Started process 18567 to run task
[2020-12-06 22:09:31,618] {logging_mixin.py:112} INFO - Running %s on host %s <TaskInstance: us_covid_daily_report_pipeline.upload_file_to_s3 2020-12-02T00:00:00+00:00 [running]> b87086861777
[2020-12-06 22:09:31,664] {taskinstance.py:1145} ERROR - upload_file_to_S3_with_hook() got an unexpected keyword argument 'conf'
Traceback (most recent call last):
  File "/home/airflow/.local/lib/python3.6/site-packages/airflow/models/taskinstance.py", line 983, in _run_raw_task
    result = task_copy.execute(context=context)
  File "/home/airflow/.local/lib/python3.6/site-packages/airflow/operators/python_operator.py", line 113, in execute
    return_value = self.execute_callable()
  File "/home/airflow/.local/lib/python3.6/site-packages/airflow/operators/python_operator.py", line 118, in execute_callable
    return self.python_callable(*self.op_args, **self.op_kwargs)
TypeError: upload_file_to_S3_with_hook() got an unexpected keyword argument 'conf'
[2020-12-06 22:09:31,666] {taskinstance.py:1202} INFO - Marking task as FAILED.dag_id=us_covid_daily_report_pipeline, task_id=upload_file_to_s3, execution_date=20201202T000000, start_date=20201206T220931, end_date=20201206T220931
[2020-12-06 22:09:41,402] {logging_mixin.py:112} INFO - [2020-12-06 22:09:41,402] {local_task_job.py:103} INFO - Task exited with return code 1
[2020-12-06 22:53:30,446] {taskinstance.py:669} INFO - Dependencies all met for <TaskInstance: us_covid_daily_report_pipeline.upload_file_to_s3 2020-12-02T00:00:00+00:00 [queued]>
[2020-12-06 22:53:30,491] {taskinstance.py:669} INFO - Dependencies all met for <TaskInstance: us_covid_daily_report_pipeline.upload_file_to_s3 2020-12-02T00:00:00+00:00 [queued]>
[2020-12-06 22:53:30,492] {taskinstance.py:879} INFO - 
--------------------------------------------------------------------------------
[2020-12-06 22:53:30,492] {taskinstance.py:880} INFO - Starting attempt 2 of 2
[2020-12-06 22:53:30,493] {taskinstance.py:881} INFO - 
--------------------------------------------------------------------------------
[2020-12-06 22:53:30,501] {taskinstance.py:900} INFO - Executing <Task(PythonOperator): upload_file_to_s3> on 2020-12-02T00:00:00+00:00
[2020-12-06 22:53:30,505] {standard_task_runner.py:53} INFO - Started process 6850 to run task
[2020-12-06 22:53:30,595] {logging_mixin.py:112} INFO - Running %s on host %s <TaskInstance: us_covid_daily_report_pipeline.upload_file_to_s3 2020-12-02T00:00:00+00:00 [running]> 0d17e5047b06
[2020-12-06 22:53:30,910] {logging_mixin.py:112} INFO - [2020-12-06 22:53:30,910] {S3_hook.py:209} INFO - Not Found
[2020-12-06 22:53:31,130] {python_operator.py:114} INFO - Done. Returned value was: None
[2020-12-06 22:53:31,147] {taskinstance.py:1065} INFO - Marking task as SUCCESS.dag_id=us_covid_daily_report_pipeline, task_id=upload_file_to_s3, execution_date=20201202T000000, start_date=20201206T225330, end_date=20201206T225331
[2020-12-06 22:53:40,398] {logging_mixin.py:112} INFO - [2020-12-06 22:53:40,398] {local_task_job.py:103} INFO - Task exited with return code 0
