[2020-12-06 21:51:17,684] {taskinstance.py:669} INFO - Dependencies all met for <TaskInstance: us_covid_daily_report_pipeline.is_covid_api_available 2020-12-05T00:00:00+00:00 [queued]>
[2020-12-06 21:51:17,743] {taskinstance.py:669} INFO - Dependencies all met for <TaskInstance: us_covid_daily_report_pipeline.is_covid_api_available 2020-12-05T00:00:00+00:00 [queued]>
[2020-12-06 21:51:17,744] {taskinstance.py:879} INFO - 
--------------------------------------------------------------------------------
[2020-12-06 21:51:17,744] {taskinstance.py:880} INFO - Starting attempt 1 of 1
[2020-12-06 21:51:17,745] {taskinstance.py:881} INFO - 
--------------------------------------------------------------------------------
[2020-12-06 21:51:17,782] {taskinstance.py:900} INFO - Executing <Task(HttpSensor): is_covid_api_available> on 2020-12-05T00:00:00+00:00
[2020-12-06 21:51:17,790] {standard_task_runner.py:53} INFO - Started process 13094 to run task
[2020-12-06 21:51:17,920] {logging_mixin.py:112} INFO - Running %s on host %s <TaskInstance: us_covid_daily_report_pipeline.is_covid_api_available 2020-12-05T00:00:00+00:00 [running]> b87086861777
[2020-12-06 21:51:17,983] {http_sensor.py:77} INFO - Poking: v1/us/20201205.json
[2020-12-06 21:51:18,005] {logging_mixin.py:112} INFO - [2020-12-06 21:51:18,004] {base_hook.py:87} INFO - Using connection to: id: covid_api. Host: https://api.covidtracking.com/, Port: None, Schema: None, Login: None, Password: None, extra: None
[2020-12-06 21:51:18,010] {logging_mixin.py:112} INFO - [2020-12-06 21:51:18,010] {http_hook.py:136} INFO - Sending 'GET' to url: https://api.covidtracking.com/v1/us/20201205.json
[2020-12-06 21:51:28,014] {logging_mixin.py:112} INFO - [2020-12-06 21:51:28,014] {http_hook.py:185} WARNING - HTTPSConnectionPool(host='api.covidtracking.com', port=443): Max retries exceeded with url: /v1/us/20201205.json (Caused by NewConnectionError('<urllib3.connection.VerifiedHTTPSConnection object at 0x7f9fc6d90470>: Failed to establish a new connection: [Errno -3] Temporary failure in name resolution',)) Tenacity will retry to execute the operation
[2020-12-06 21:51:28,016] {taskinstance.py:1145} ERROR - HTTPSConnectionPool(host='api.covidtracking.com', port=443): Max retries exceeded with url: /v1/us/20201205.json (Caused by NewConnectionError('<urllib3.connection.VerifiedHTTPSConnection object at 0x7f9fc6d90470>: Failed to establish a new connection: [Errno -3] Temporary failure in name resolution',))
Traceback (most recent call last):
  File "/home/airflow/.local/lib/python3.6/site-packages/urllib3/connection.py", line 157, in _new_conn
    (self._dns_host, self.port), self.timeout, **extra_kw
  File "/home/airflow/.local/lib/python3.6/site-packages/urllib3/util/connection.py", line 61, in create_connection
    for res in socket.getaddrinfo(host, port, family, socket.SOCK_STREAM):
  File "/usr/local/lib/python3.6/socket.py", line 745, in getaddrinfo
    for res in _socket.getaddrinfo(host, port, family, type, proto, flags):
socket.gaierror: [Errno -3] Temporary failure in name resolution

During handling of the above exception, another exception occurred:

Traceback (most recent call last):
  File "/home/airflow/.local/lib/python3.6/site-packages/urllib3/connectionpool.py", line 672, in urlopen
    chunked=chunked,
  File "/home/airflow/.local/lib/python3.6/site-packages/urllib3/connectionpool.py", line 376, in _make_request
    self._validate_conn(conn)
  File "/home/airflow/.local/lib/python3.6/site-packages/urllib3/connectionpool.py", line 994, in _validate_conn
    conn.connect()
  File "/home/airflow/.local/lib/python3.6/site-packages/urllib3/connection.py", line 300, in connect
    conn = self._new_conn()
  File "/home/airflow/.local/lib/python3.6/site-packages/urllib3/connection.py", line 169, in _new_conn
    self, "Failed to establish a new connection: %s" % e
urllib3.exceptions.NewConnectionError: <urllib3.connection.VerifiedHTTPSConnection object at 0x7f9fc6d90470>: Failed to establish a new connection: [Errno -3] Temporary failure in name resolution

During handling of the above exception, another exception occurred:

Traceback (most recent call last):
  File "/home/airflow/.local/lib/python3.6/site-packages/requests/adapters.py", line 449, in send
    timeout=timeout
  File "/home/airflow/.local/lib/python3.6/site-packages/urllib3/connectionpool.py", line 720, in urlopen
    method, url, error=e, _pool=self, _stacktrace=sys.exc_info()[2]
  File "/home/airflow/.local/lib/python3.6/site-packages/urllib3/util/retry.py", line 436, in increment
    raise MaxRetryError(_pool, url, error or ResponseError(cause))
urllib3.exceptions.MaxRetryError: HTTPSConnectionPool(host='api.covidtracking.com', port=443): Max retries exceeded with url: /v1/us/20201205.json (Caused by NewConnectionError('<urllib3.connection.VerifiedHTTPSConnection object at 0x7f9fc6d90470>: Failed to establish a new connection: [Errno -3] Temporary failure in name resolution',))

During handling of the above exception, another exception occurred:

Traceback (most recent call last):
  File "/home/airflow/.local/lib/python3.6/site-packages/airflow/models/taskinstance.py", line 983, in _run_raw_task
    result = task_copy.execute(context=context)
  File "/home/airflow/.local/lib/python3.6/site-packages/airflow/sensors/base_sensor_operator.py", line 107, in execute
    while not self.poke(context):
  File "/home/airflow/.local/lib/python3.6/site-packages/airflow/sensors/http_sensor.py", line 82, in poke
    extra_options=self.extra_options)
  File "/home/airflow/.local/lib/python3.6/site-packages/airflow/hooks/http_hook.py", line 137, in run
    return self.run_and_check(session, prepped_request, extra_options)
  File "/home/airflow/.local/lib/python3.6/site-packages/airflow/hooks/http_hook.py", line 186, in run_and_check
    raise ex
  File "/home/airflow/.local/lib/python3.6/site-packages/airflow/hooks/http_hook.py", line 178, in run_and_check
    allow_redirects=extra_options.get("allow_redirects", True))
  File "/home/airflow/.local/lib/python3.6/site-packages/requests/sessions.py", line 643, in send
    r = adapter.send(request, **kwargs)
  File "/home/airflow/.local/lib/python3.6/site-packages/requests/adapters.py", line 516, in send
    raise ConnectionError(e, request=request)
requests.exceptions.ConnectionError: HTTPSConnectionPool(host='api.covidtracking.com', port=443): Max retries exceeded with url: /v1/us/20201205.json (Caused by NewConnectionError('<urllib3.connection.VerifiedHTTPSConnection object at 0x7f9fc6d90470>: Failed to establish a new connection: [Errno -3] Temporary failure in name resolution',))
[2020-12-06 21:51:28,022] {taskinstance.py:1202} INFO - Marking task as FAILED.dag_id=us_covid_daily_report_pipeline, task_id=is_covid_api_available, execution_date=20201205T000000, start_date=20201206T215117, end_date=20201206T215128
[2020-12-06 21:51:32,668] {logging_mixin.py:112} INFO - [2020-12-06 21:51:32,668] {local_task_job.py:103} INFO - Task exited with return code 1
[2020-12-06 22:50:17,420] {taskinstance.py:669} INFO - Dependencies all met for <TaskInstance: us_covid_daily_report_pipeline.is_covid_api_available 2020-12-05T00:00:00+00:00 [queued]>
[2020-12-06 22:50:17,479] {taskinstance.py:669} INFO - Dependencies all met for <TaskInstance: us_covid_daily_report_pipeline.is_covid_api_available 2020-12-05T00:00:00+00:00 [queued]>
[2020-12-06 22:50:17,479] {taskinstance.py:879} INFO - 
--------------------------------------------------------------------------------
[2020-12-06 22:50:17,481] {taskinstance.py:880} INFO - Starting attempt 1 of 1
[2020-12-06 22:50:17,482] {taskinstance.py:881} INFO - 
--------------------------------------------------------------------------------
[2020-12-06 22:50:17,520] {taskinstance.py:900} INFO - Executing <Task(HttpSensor): is_covid_api_available> on 2020-12-05T00:00:00+00:00
[2020-12-06 22:50:17,528] {standard_task_runner.py:53} INFO - Started process 5732 to run task
[2020-12-06 22:50:17,702] {logging_mixin.py:112} INFO - Running %s on host %s <TaskInstance: us_covid_daily_report_pipeline.is_covid_api_available 2020-12-05T00:00:00+00:00 [running]> 0d17e5047b06
[2020-12-06 22:50:17,784] {http_sensor.py:77} INFO - Poking: v1/us/20201205.json
[2020-12-06 22:50:17,826] {logging_mixin.py:112} INFO - [2020-12-06 22:50:17,822] {base_hook.py:87} INFO - Using connection to: id: covid_api. Host: https://api.covidtracking.com, Port: None, Schema: None, Login: None, Password: None, extra: None
[2020-12-06 22:50:17,833] {logging_mixin.py:112} INFO - [2020-12-06 22:50:17,833] {http_hook.py:136} INFO - Sending 'GET' to url: https://api.covidtracking.com/v1/us/20201205.json
[2020-12-06 22:50:17,894] {logging_mixin.py:112} WARNING - /home/airflow/.local/lib/python3.6/site-packages/urllib3/connectionpool.py:1004: InsecureRequestWarning: Unverified HTTPS request is being made to host 'api.covidtracking.com'. Adding certificate verification is strongly advised. See: https://urllib3.readthedocs.io/en/latest/advanced-usage.html#ssl-warnings
  InsecureRequestWarning,
[2020-12-06 22:50:17,906] {base_sensor_operator.py:123} INFO - Success criteria met. Exiting.
[2020-12-06 22:50:17,932] {taskinstance.py:1065} INFO - Marking task as SUCCESS.dag_id=us_covid_daily_report_pipeline, task_id=is_covid_api_available, execution_date=20201205T000000, start_date=20201206T225017, end_date=20201206T225017
[2020-12-06 22:50:27,352] {logging_mixin.py:112} INFO - [2020-12-06 22:50:27,351] {local_task_job.py:103} INFO - Task exited with return code 0
